Workbook

Sheet Daily_Profits_Calculations
A1: Date | B1: UserID | C1: Name | D1: User_Invested_Amount | E1: Transaction_ID | F1: Transaction_Date | G1: User_Invest_Amount_As_On_Date | H1: Company_Total_Investment_As_On_Date | I1: Total_Profit | J1: Profit_% | K1: Profit | L1: Payment_Status
A2: 45978 | B2: U001 | C2: Arun | D2: 1700 | E2: T001ADD1700 | F2: 45977 | G2: 1700 | H2: 1700 | I2: 10.13 | J2: 1 | K2: =Table1[[#This Row],[Total_Profit]]*Table1[[#This Row],[Profit_%]] -> 10.13 | L2: Completed
A3: 45979 | B3: U001 | C3: Arun | G3: 1700 | H3: 1700 | I3: 31.68 | J3: 1 | K3: =Table1[[#This Row],[Total_Profit]]*Table1[[#This Row],[Profit_%]] -> 31.68 | L3: Completed
A4: 45980 | B4: U001 | C4: Arun | G4: 1700 | H4: 1700 | I4: 98.08 | J4: 1 | K4: =Table1[[#This Row],[Total_Profit]]*Table1[[#This Row],[Profit_%]] -> 98.08 | L4: Completed
A5: 45981 | B5: U001 | C5: Arun | G5: 1700 | H5: 2700 | I5: 101.9 | J5: =Table1[[#This Row],[User_Invest_Amount_As_On_Date]]/Table1[[#This Row],[Company_Total_Investment_As_On_Date]] -> 0.62962963 | K5: =Table1[[#This Row],[Total_Profit]]*Table1[[#This Row],[Profit_%]] -> 64.159259 | L5: Completed
A6: 45981 | B6: U002 | C6: Grp Mem Mumtaj | D6: 500 | E6: T002ADD500 | F6: 45980 | G6: 500 | H6: 2700 | I6: 101.9 | J6: =Table1[[#This Row],[User_Invest_Amount_As_On_Date]]/Table1[[#This Row],[Company_Total_Investment_As_On_Date]] -> 0.18518519 | K6: =Table1[[#This Row],[Total_Profit]]*Table1[[#This Row],[Profit_%]] -> 18.87037 | L6: Completed
A7: 45981 | B7: U003 | C7: Grp Mem Balram | D7: 500 | E7: T003ADD500 | F7: 45980 | G7: 500 | H7: 2700 | I7: 101.9 | J7: =Table1[[#This Row],[User_Invest_Amount_As_On_Date]]/Table1[[#This Row],[Company_Total_Investment_As_On_Date]] -> 0.18518519 | K7: =Table1[[#This Row],[Total_Profit]]*Table1[[#This Row],[Profit_%]] -> 18.87037 | L7: Completed
A8: 45982 | B8: U001 | C8: Arun | G8: 1700 | H8: 6700 | I8: 105.2 | J8: =Table1[[#This Row],[User_Invest_Amount_As_On_Date]]/Table1[[#This Row],[Company_Total_Investment_As_On_Date]] -> 0.25373134 | K8: =Table1[[#This Row],[Total_Profit]]*Table1[[#This Row],[Profit_%]] -> 26.692537 | L8: Completed
A9: 45982 | B9: U002 | C9: Grp Mem Mumtaj | G9: 500 | H9: 6700 | I9: 105.2 | J9: =Table1[[#This Row],[User_Invest_Amount_As_On_Date]]/Table1[[#This Row],[Company_Total_Investment_As_On_Date]] -> 0.074626866 | K9: =Table1[[#This Row],[Total_Profit]]*Table1[[#This Row],[Profit_%]] -> 7.8507463 | L9: Completed
A10: 45982 | B10: U003 | C10: Grp Mem Balram | G10: 500 | H10: 6700 | I10: 105.2 | J10: =Table1[[#This Row],[User_Invest_Amount_As_On_Date]]/Table1[[#This Row],[Company_Total_Investment_As_On_Date]] -> 0.074626866 | K10: =Table1[[#This Row],[Total_Profit]]*Table1[[#This Row],[Profit_%]] -> 7.8507463 | L10: Completed
A11: 45982 | B11: U004 | C11: Bigil | D11: 1500 | E11: T004ADD1500 | F11: 45981 | G11: 1500 | H11: 6700 | I11: 105.2 | J11: =Table1[[#This Row],[User_Invest_Amount_As_On_Date]]/Table1[[#This Row],[Company_Total_Investment_As_On_Date]] -> 0.2238806 | K11: =Table1[[#This Row],[Total_Profit]]*Table1[[#This Row],[Profit_%]] -> 23.552239 | L11: Completed
A12: 45982 | B12: U005 | C12: Vending Machine Referer | D12: 500 | E12: T005ADD500 | F12: 45981 | G12: 500 | H12: 6700 | I12: 105.2 | J12: =Table1[[#This Row],[User_Invest_Amount_As_On_Date]]/Table1[[#This Row],[Company_Total_Investment_As_On_Date]] -> 0.074626866 | K12: =Table1[[#This Row],[Total_Profit]]*Table1[[#This Row],[Profit_%]] -> 7.8507463 | L12: Completed
A13: 45982 | B13: U006 | C13: Grp Mem Athithya | D13: 2000 | E13: T006ADD2000 | F13: 45981 | G13: 2000 | H13: 6700 | I13: 105.2 | J13: =Table1[[#This Row],[User_Invest_Amount_As_On_Date]]/Table1[[#This Row],[Company_Total_Investment_As_On_Date]] -> 0.29850746 | K13: =Table1[[#This Row],[Total_Profit]]*Table1[[#This Row],[Profit_%]] -> 31.402985 | L13: Completed
A14: 45983 | B14: U001 | C14: Arun | G14: 1700 | H14: 7700 | I14: -1670 | J14: =Table1[[#This Row],[User_Invest_Amount_As_On_Date]]/Table1[[#This Row],[Company_Total_Investment_As_On_Date]] -> 0.22077922 | K14: =Table1[[#This Row],[Total_Profit]]*Table1[[#This Row],[Profit_%]] -> -368.7013 | L14: Recovered
A15: 45983 | B15: U002 | C15: Grp Mem Mumtaj | D15: 1000 | E15: T007ADD1000 | F15: 45982 | G15: 1500 | H15: 7700 | I15: -1670 | J15: =Table1[[#This Row],[User_Invest_Amount_As_On_Date]]/Table1[[#This Row],[Company_Total_Investment_As_On_Date]] -> 0.19480519 | K15: =Table1[[#This Row],[Total_Profit]]*Table1[[#This Row],[Profit_%]] -> -325.32468 | L15: Recovered
A16: 45983 | B16: U003 | C16: Grp Mem Balram | G16: 500 | H16: 7700 | I16: -1670 | J16: =Table1[[#This Row],[User_Invest_Amount_As_On_Date]]/Table1[[#This Row],[Company_Total_Investment_As_On_Date]] -> 0.064935065 | K16: =Table1[[#This Row],[Total_Profit]]*Table1[[#This Row],[Profit_%]] -> -108.44156 | L16: Recovered
A17: 45983 | B17: U004 | C17: Bigil | G17: 1500 | H17: 7700 | I17: -1670 | J17: =Table1[[#This Row],[User_Invest_Amount_As_On_Date]]/Table1[[#This Row],[Company_Total_Investment_As_On_Date]] -> 0.19480519 | K17: =Table1[[#This Row],[Total_Profit]]*Table1[[#This Row],[Profit_%]] -> -325.32468 | L17: Recovered
A18: 45983 | B18: U005 | C18: Vending Machine Referer | G18: 500 | H18: 7700 | I18: -1670 | J18: =Table1[[#This Row],[User_Invest_Amount_As_On_Date]]/Table1[[#This Row],[Company_Total_Investment_As_On_Date]] -> 0.064935065 | K18: =Table1[[#This Row],[Total_Profit]]*Table1[[#This Row],[Profit_%]] -> -108.44156 | L18: Recovered
A19: 45983 | B19: U006 | C19: Grp Mem Athithya | G19: 2000 | H19: 7700 | I19: -1670 | J19: =Table1[[#This Row],[User_Invest_Amount_As_On_Date]]/Table1[[#This Row],[Company_Total_Investment_As_On_Date]] -> 0.25974026 | K19: =Table1[[#This Row],[Total_Profit]]*Table1[[#This Row],[Profit_%]] -> -433.76623 | L19: Recovered
A21: 45992 | B21: U001 | C21: Arun | D21: 300 | E21: T008ADD300 | F21: 11/302025 | G21: 2000 | H21: 8000 | I21: 230 | J21: =Table1[[#This Row],[User_Invest_Amount_As_On_Date]]/Table1[[#This Row],[Company_Total_Investment_As_On_Date]] -> 0.25 | K21: =Table1[[#This Row],[Total_Profit]]*Table1[[#This Row],[Profit_%]] -> 57.5 | L21: Completed
A22: 45992 | B22: U002 | C22: Grp Mem Mumtaj | G22: 1500 | H22: 8000 | I22: 230 | J22: =Table1[[#This Row],[User_Invest_Amount_As_On_Date]]/Table1[[#This Row],[Company_Total_Investment_As_On_Date]] -> 0.1875 | K22: =Table1[[#This Row],[Total_Profit]]*Table1[[#This Row],[Profit_%]] -> 43.125 | L22: Completed
A23: 45992 | B23: U003 | C23: Grp Mem Balram | G23: 500 | H23: 8000 | I23: 230 | J23: =Table1[[#This Row],[User_Invest_Amount_As_On_Date]]/Table1[[#This Row],[Company_Total_Investment_As_On_Date]] -> 0.0625 | K23: =Table1[[#This Row],[Total_Profit]]*Table1[[#This Row],[Profit_%]] -> 14.375 | L23: Completed
A24: 45992 | B24: U004 | C24: Bigil | G24: 1500 | H24: 8000 | I24: 230 | J24: =Table1[[#This Row],[User_Invest_Amount_As_On_Date]]/Table1[[#This Row],[Company_Total_Investment_As_On_Date]] -> 0.1875 | K24: =Table1[[#This Row],[Total_Profit]]*Table1[[#This Row],[Profit_%]] -> 43.125 | L24: Completed
A25: 45992 | B25: U005 | C25: Vending Machine Referer | G25: 500 | H25: 8000 | I25: 230 | J25: =Table1[[#This Row],[User_Invest_Amount_As_On_Date]]/Table1[[#This Row],[Company_Total_Investment_As_On_Date]] -> 0.0625 | K25: =Table1[[#This Row],[Total_Profit]]*Table1[[#This Row],[Profit_%]] -> 14.375 | L25: Completed
A26: 45992 | B26: U006 | C26: Grp Mem Athithya | G26: 2000 | H26: 8000 | I26: 230 | J26: =Table1[[#This Row],[User_Invest_Amount_As_On_Date]]/Table1[[#This Row],[Company_Total_Investment_As_On_Date]] -> 0.25 | K26: =Table1[[#This Row],[Total_Profit]]*Table1[[#This Row],[Profit_%]] -> 57.5 | L26: Completed
A28: 45993 | B28: U001 | C28: Arun | G28: 2000 | H28: 8000 | I28: 416 | J28: =Table1[[#This Row],[User_Invest_Amount_As_On_Date]]/Table1[[#This Row],[Company_Total_Investment_As_On_Date]] -> 0.25 | K28: =Table1[[#This Row],[Total_Profit]]*Table1[[#This Row],[Profit_%]] -> 104 | L28: Completed
A29: 45993 | B29: U002 | C29: Grp Mem Mumtaj | G29: 1500 | H29: 8000 | I29: 416 | J29: =Table1[[#This Row],[User_Invest_Amount_As_On_Date]]/Table1[[#This Row],[Company_Total_Investment_As_On_Date]] -> 0.1875 | K29: =Table1[[#This Row],[Total_Profit]]*Table1[[#This Row],[Profit_%]] -> 78 | L29: Completed
A30: 45993 | B30: U003 | C30: Grp Mem Balram | G30: 500 | H30: 8000 | I30: 416 | J30: =Table1[[#This Row],[User_Invest_Amount_As_On_Date]]/Table1[[#This Row],[Company_Total_Investment_As_On_Date]] -> 0.0625 | K30: =Table1[[#This Row],[Total_Profit]]*Table1[[#This Row],[Profit_%]] -> 26 | L30: Completed
A31: 45993 | B31: U004 | C31: Bigil | G31: 1500 | H31: 8000 | I31: 416 | J31: =Table1[[#This Row],[User_Invest_Amount_As_On_Date]]/Table1[[#This Row],[Company_Total_Investment_As_On_Date]] -> 0.1875 | K31: =Table1[[#This Row],[Total_Profit]]*Table1[[#This Row],[Profit_%]] -> 78 | L31: Completed
A32: 45993 | B32: U005 | C32: Vending Machine Referer | G32: 500 | H32: 8000 | I32: 416 | J32: =Table1[[#This Row],[User_Invest_Amount_As_On_Date]]/Table1[[#This Row],[Company_Total_Investment_As_On_Date]] -> 0.0625 | K32: =Table1[[#This Row],[Total_Profit]]*Table1[[#This Row],[Profit_%]] -> 26 | L32: Completed
A33: 45993 | B33: U006 | C33: Grp Mem Athithya | G33: 2000 | H33: 8000 | I33: 416 | J33: =Table1[[#This Row],[User_Invest_Amount_As_On_Date]]/Table1[[#This Row],[Company_Total_Investment_As_On_Date]] -> 0.25 | K33: =Table1[[#This Row],[Total_Profit]]*Table1[[#This Row],[Profit_%]] -> 104 | L33: Completed
A35: 45994 | B35: U001 | C35: Arun | G35: 2000 | H35: 10000 | I35: 300 | J35: =Table1[[#This Row],[User_Invest_Amount_As_On_Date]]/Table1[[#This Row],[Company_Total_Investment_As_On_Date]] -> 0.2 | K35: =Table1[[#This Row],[Total_Profit]]*Table1[[#This Row],[Profit_%]] -> 60 | L35: Completed
... A40: 45994 | B40: U006 | C40: Grp Mem Athithya | G40: 2000 | H40: 10000 | I40: 300 | J40: =Table1[[#This Row],[User_Invest_Amount_As_On_Date]]/Table1[[#This Row],[Company_Total_Investment_As_On_Date]] -> 0.2 | K40: =Table1[[#This Row],[Total_Profit]]*Table1[[#This Row],[Profit_%]] -> 60 | L40: Completed
A41: 45994 | B41: U007 | C41: Chinni | D41: 2000 | E41: T009ADD2000 | F41: 45993 | G41: 2000 | H41: 10000 | I41: 300 | J41: =Table1[[#This Row],[User_Invest_Amount_As_On_Date]]/Table1[[#This Row],[Company_Total_Investment_As_On_Date]] -> 0.2 | K41: =Table1[[#This Row],[Total_Profit]]*Table1[[#This Row],[Profit_%]] -> 60 | L41: Completed
A43: 45995 | B43: U001 | C43: Arun | G43: 2000 | H43: 10000 | I43: 411 | J43: =Table1[[#This Row],[User_Invest_Amount_As_On_Date]]/Table1[[#This Row],[Company_Total_Investment_As_On_Date]] -> 0.2 | K43: =Table1[[#This Row],[Total_Profit]]*Table1[[#This Row],[Profit_%]] -> 82.2 | L43: Completed
A44: 45995 | B44: U002 | C44: Grp Mem Mumtaj | G44: 1500 | H44: 10000 | I44: 411 | J44: =Table1[[#This Row],[User_Invest_Amount_As_On_Date]]/Table1[[#This Row],[Company_Total_Investment_As_On_Date]] -> 0.15 | K44: =Table1[[#This Row],[Total_Profit]]*Table1[[#This Row],[Profit_%]] -> 61.65 | L44: Completed
A45: 45995 | B45: U003 | C45: Grp Mem Balram | G45: 500 | H45: 10000 | I45: 411 | J45: =Table1[[#This Row],[User_Invest_Amount_As_On_Date]]/Table1[[#This Row],[Company_Total_Investment_As_On_Date]] -> 0.05 | K45: =Table1[[#This Row],[Total_Profit]]*Table1[[#This Row],[Profit_%]] -> 20.55 | L45: Completed
A46: 45995 | B46: U004 | C46: Bigil | G46: 1500 | H46: 10000 | I46: 411 | J46: =Table1[[#This Row],[User_Invest_Amount_As_On_Date]]/Table1[[#This Row],[Company_Total_Investment_As_On_Date]] -> 0.15 | K46: =Table1[[#This Row],[Total_Profit]]*Table1[[#This Row],[Profit_%]] -> 61.65 | L46: Completed
A47: 45995 | B47: U005 | C47: Vending Machine Referer | G47: 500 | H47: 10000 | I47: 411 | J47: =Table1[[#This Row],[User_Invest_Amount_As_On_Date]]/Table1[[#This Row],[Company_Total_Investment_As_On_Date]] -> 0.05 | K47: =Table1[[#This Row],[Total_Profit]]*Table1[[#This Row],[Profit_%]] -> 20.55 | L47: Completed
A48: 45995 | B48: U006 | C48: Grp Mem Athithya | G48: 2000 | H48: 10000 | I48: 411 | J48: =Table1[[#This Row],[User_Invest_Amount_As_On_Date]]/Table1[[#This Row],[Company_Total_Investment_As_On_Date]] -> 0.2 | K48: =Table1[[#This Row],[Total_Profit]]*Table1[[#This Row],[Profit_%]] -> 82.2 | L48: Completed
...

Sheet Investor_Details
A1: UserID | B1: Contact_Name | C1: Name | D1: Total_Invested_Amount | E1: Total Profit Earned | F1: UPI
A2: U001 | B2: Arun | C2: Arun | D2: 2500 | E2: =SUMIFS(Daily_Report!E:E,Daily_Report!B:B,Table2[[#This Row],[UserID]]) -> 1198.6488 | F2: Myself
A3: U002 | B3: Grp Mem Mumtaj | C3: Mohd Shoaib | D3: 1500 | E3: =SUMIFS(Daily_Report!E:E,Daily_Report!B:B,Table2[[#This Row],[UserID]]) -> 829.31884 | F3: Shoaib.1@superyes
A4: U003 | B4: Grp Mem Balram | C4: Balaram | D4: 500 | E4: =SUMIFS(Daily_Report!E:E,Daily_Report!B:B,Table2[[#This Row],[UserID]]) -> 294.25369 | F4: 6372971081@ybl
A5: U004 | B5: Bigil | C5: Sriram Ranjith | D5: 1500 | E5: =SUMIFS(Daily_Report!E:E,Daily_Report!B:B,Table2[[#This Row],[UserID]]) -> 826.14997 | F5: sriramranjith1999-2@okicici
A6: U005 | B6: Vending Machine Referer | C6: Mubashar Sarfraz | D6: 1000 | E6: =SUMIFS(Daily_Report!E:E,Daily_Report!B:B,Table2[[#This Row],[UserID]]) -> 313.04999 | F6: 8492066060@indie
A7: U006 | B7: Grp Mem Athithya | C7: Aathithya | D7: 2000 | E7: =SUMIFS(Daily_Report!E:E,Daily_Report!B:B,Table2[[#This Row],[UserID]]) -> 1101.5333 | F7: selva.aathi12-8@okicici
A8: U007 | B8: Chinni | C8: Chinni | D8: 2000 | E8: =SUMIFS(Daily_Report!E:E,Daily_Report!B:B,Table2[[#This Row],[UserID]]) -> 908.6303 | F8: 9515974700@ybl
A9: U008 | B9: Pradip | C9: Pradip | D9: 1000 | E9: =SUMIFS(Daily_Report!E:E,Daily_Report!B:B,Table2[[#This Row],[UserID]]) -> 231.51515 | F9: pradeepganapa@ybl

Sheet Daily_Report
A1: Date | B1: UserID | C1: Invest_Amount | D1: Company_Total_Invest | E1: Profit | F1: Payment
A2: 45981 | B2: U001 | C2: 1700 | D2: 2700 | E2: 64.159259 | F2: Completed
A3: 45981 | B3: U002 | C3: 500 | D3: 2700 | E3: 18.87037 | F3: Completed
A4: 45981 | B4: U003 | C4: 500 | D4: 2700 | E4: 18.87037 | F4: Completed
A5: 45982 | B5: U001 | C5: 1700 | D5: 6700 | E5: 26.692537 | F5: Completed
A6: 45982 | B6: U002 | C6: 500 | D6: 6700 | E6: 7.8507463 | F6: Completed
A7: 45982 | B7: U003 | C7: 500 | D7: 6700 | E7: 7.8507463 | F7: Completed
A8: 45982 | B8: U004 | C8: 1500 | D8: 6700 | E8: 23.552239 | F8: Completed
A9: 45982 | B9: U005 | C9: 500 | D9: 6700 | E9: 7.8507463 | F9: Completed
A10: 45982 | B10: U006 | C10: 2000 | D10: 6700 | E10: 31.402985 | F10: Completed
A12: 45992 | B12: U001 | C12: 2000 | D12: 8000 | E12: 57.5 | F12: Completed
A13: 45992 | B13: U002 | C13: 1500 | D13: 8000 | E13: 43.125 | F13: Completed
A14: 45992 | B14: U003 | C14: 500 | D14: 8000 | E14: 14.375 | F14: Completed
... A109: 46005 | B109: U008 | C109: 1000 | D109: 12000 | E109: 36.166667 | F109: Pending

Sheet Loss_Recovery
A1: Date | B1: Total Profit
A2: 45997 | B2: 402 | F2: Date | G2: 45996
A3: 45998 | B3: 447 | F3: Loss | G3: 758
F4: Recovered | G4: =SUM(Table3[Total Profit]) -> 849
F5: Remaining | G5: =G3-G4 -> -91

Sheet Platofrm_Maintaince_Charges
A1: UserID | B1: Reason_For_Charge | C1: Charge_Amt | D1: Charge_Per_Head | E1: Paid_Amt | F1: Pending_Amt
A2: U001 | B2: KYC Recharge Charges For VPS | C2: 220 | D2: 31.42 | E2: 31.42 | F2: =Table5[[#This Row],[Charge_Per_Head]]-Table5[[#This Row],[Paid_Amt]] -> 0
A3: U002 | B3: KYC Recharge Charges For VPS | C3: 220 | D3: 31.42 | E3: 31.42 | F3: =Table5[[#This Row],[Charge_Per_Head]]-Table5[[#This Row],[Paid_Amt]] -> 0
A4: U003 | B4: KYC Recharge Charges For VPS | C4: 220 | D4: 31.42 | E4: 31.42 | F4: =Table5[[#This Row],[Charge_Per_Head]]-Table5[[#This Row],[Paid_Amt]] -> 0
A5: U004 | B5: KYC Recharge Charges For VPS | C5: 220 | D5: 31.42 | E5: 31.42 | F5: =Table5[[#This Row],[Charge_Per_Head]]-Table5[[#This Row],[Paid_Amt]] -> 0
A6: U005 | B6: KYC Recharge Charges For VPS | C6: 220 | D6: 31.42 | E6: 31.42 | F6: =Table5[[#This Row],[Charge_Per_Head]]-Table5[[#This Row],[Paid_Amt]] -> 0
A7: U006 | B7: KYC Recharge Charges For VPS | C7: 220 | D7: 31.42 | E7: 31.42 | F7: =Table5[[#This Row],[Charge_Per_Head]]-Table5[[#This Row],[Paid_Amt]] -> 0
A8: U007 | B8: KYC Recharge Charges For VPS | C8: 220 | D8: 31.42 | E8: 31.42 | F8: =Table5[[#This Row],[Charge_Per_Head]]-Table5[[#This Row],[Paid_Amt]] -> 0
A9: U001 | B9: VPS Charges For 10th Dec'2025 | C9: 1764 | D9: 220.5 | E9: 220.5 | F9: =Table5[[#This Row],[Charge_Per_Head]]-Table5[[#This Row],[Paid_Amt]] -> 0
A10: U002 | B10: VPS Charges For 10th Dec'2025 | C10: 1764 | D10: 220.5 | E10: 220.5 | F10: =Table5[[#This Row],[Charge_Per_Head]]-Table5[[#This Row],[Paid_Amt]] -> 0
A11: U003 | B11: VPS Charges For 10th Dec'2025 | C11: 1764 | D11: 220.5 | E11: 220.5 | F11: =Table5[[#This Row],[Charge_Per_Head]]-Table5[[#This Row],[Paid_Amt]] -> 0
A12: U004 | B12: VPS Charges For 10th Dec'2025 | C12: 1764 | D12: 220.5 | E12: 220.5 | F12: =Table5[[#This Row],[Charge_Per_Head]]-Table5[[#This Row],[Paid_Amt]] -> 0
A13: U005 | B13: VPS Charges For 10th Dec'2025 | C13: 1764 | D13: 220.5 | E13: 220.5 | F13: =Table5[[#This Row],[Charge_Per_Head]]-Table5[[#This Row],[Paid_Amt]] -> 0
... A16: U008 | B16: VPS Charges For 10th Dec'2025 | C16: 1764 | D16: 220.5 | E16: 220.5 | F16: =Table5[[#This Row],[Charge_Per_Head]]-Table5[[#This Row],[Paid_Amt]] -> 0

Sheet Rough Sheet
C4: UserID | D4: Invested_Amount
C5: U001 | D5: 2000
C6: U002 | D6: 1500
C7: U003 | D7: 500
C8: U004 | D8: 1500 | O8: balram | P8: 26.72
C9: U005 | D9: 500 | O9: mumtaj | P9: 26.72
C10: U006 | D10: 2000 | O10: bigil | P10: 23.55
C11: U007 | D11: 2000 | O11: vending | P11: 7.85
O12: athithya | P12: 31.4
G14: UserID | H14: Invested_Amount | I14: Profit_%
G15: U001 | H15: 2000 | I15: 0.25
G16: U002 | H16: 1500 | I16: 0.1875
G17: U003 | H17: 500 | I17: 0.0625
G18: U004 | H18: 1500 | I18: 0.1875
G19: U005 | H19: 500 | I19: 0.0625
G20: U006 | H20: 2000 | I20: 0.25 | N20: 241 | O20: 32 | P20: =N20-O20 -> 209
L24: 60.25
L25: 180.75
L26: 60.25 | N26: 6505 | O26: 5773 | P26: =N26-O26 -> 732
L27: 180.75
L28: 241
L29: 209
